// Error handling utilities for better user experience
export class AppError extends Error {
  constructor(
    message: string,
    public code?: string,
    public statusCode?: number
  ) {
    super(message);
    this.name = 'AppError';
  }
}

export const handleAsyncError = <T extends any[], R>(
  fn: (...args: T) => Promise<R>
) => {
  return async (...args: T): Promise<R | null> => {
    try {
      return await fn(...args);
    } catch (error) {
      console.error('Async operation failed:', error);
      return null;
    }
  };
};

export const withRetry = async <T>(
  operation: () => Promise<T>,
  maxRetries: number = 3,
  delay: number = 1000
): Promise<T> => {
  let lastError: Error;
  
  for (let i = 0; i < maxRetries; i++) {
    try {
      return await operation();
    } catch (error) {
      lastError = error as Error;
      if (i < maxRetries - 1) {
        await new Promise(resolve => setTimeout(resolve, delay * Math.pow(2, i)));
      }
    }
  }
  
  throw lastError!;
};

// Storage utilities with error handling
export const safeLocalStorage = {
  getItem: (key: string): string | null => {
    try {
      return localStorage.getItem(key);
    } catch (error) {
      console.warn('Failed to read from localStorage:', error);
      return null;
    }
  },
  
  setItem: (key: string, value: string): boolean => {
    try {
      localStorage.setItem(key, value);
      return true;
    } catch (error) {
      console.warn('Failed to write to localStorage:', error);
      return false;
    }
  },
  
  removeItem: (key: string): boolean => {
    try {
      localStorage.removeItem(key);
      return true;
    } catch (error) {
      console.warn('Failed to remove from localStorage:', error);
      return false;
    }
  }
};